<?xml version="1.0" ?>
<!-- =================================================================================== -->
<!-- |    This document was autogenerated by xacro from /home/aurone/projects/ros/rcta_ws/src/roman_model/robots/rcta_roman.urdf.xacro | -->
<!-- |    EDITING THIS FILE BY HAND IS NOT RECOMMENDED                                 | -->
<!-- =================================================================================== -->
<robot name="rcta_roman" xmlns:xacro="http://ros.org/wiki/xacro">
  <gazebo>
    <static>false</static>
    <plugin filename="libgazebo_ros_control.so" name="gazebo_ros_control">
      <robotSimType>gazebo_ros_control/DefaultRobotHWSim</robotSimType>
    </plugin>
  </gazebo>
  <link name="base_link">
    <visual>
      <origin rpy="0 0 0" xyz="0 0 0"/>
      <geometry>
        <box size="0 0 0"/>
      </geometry>
      <material name="white">
        <color rgba="1 1 1 1"/>
      </material>
    </visual>
    <collision>
      <origin rpy="0 0 0" xyz="0 0 0"/>
      <geometry>
        <box size="0 0 0"/>
      </geometry>
    </collision>
  </link>
  <joint name="base_joint" type="fixed">
    <origin rpy="3.14 0 0" xyz="0 0 0"/>
    <parent link="base_link"/>
    <child link="talon"/>
  </joint>
  <link name="talon">
    <inertial>
      <mass value="40.000000"/>
      <origin rpy="0 0 0" xyz="0.000000 0.000000 0.000000"/>
      <inertia ixx="0.000000" ixy="0.000000" ixz="0.000000" iyy="0.000000" iyz="0.000000" izz="0.000000"/>
    </inertial>
    <visual>
      <origin rpy="0 0 0" xyz="0 0 0"/>
      <geometry>
        <!--                    <box size="0.900000 0.600000 0.260000"/> -->
        <mesh filename="package://roman_model/meshes/talon.stl" scale="1 1 1"/>
      </geometry>
      <material name="grey">
        <color rgba=".8 .8 .8 1"/>
      </material>
    </visual>
    <collision>
      <origin rpy="0 0 0" xyz="0.000000 0.000000 0.000000"/>
      <geometry>
        <box size="0.900000 0.600000 0.260000"/>
      </geometry>
    </collision>
    <collision>
      <origin rpy="0 0 0" xyz="0.000000 0.260000 0.000000"/>
      <geometry>
        <box size="0.900000 0.080000 0.300000"/>
      </geometry>
    </collision>
    <collision>
      <origin rpy="0 0 0" xyz="0.000000 -0.260000 0.000000"/>
      <geometry>
        <box size="0.900000 0.080000 0.300000"/>
      </geometry>
    </collision>
    <collision>
      <origin rpy="0 0 0" xyz="-0.325000 0.000000 -0.180000"/>
      <geometry>
        <box size="0.250000 0.600000 0.100000"/>
      </geometry>
    </collision>
  </link>
  <link name="track_left">
    <inertial>
      <mass value="0.000000"/>
      <origin rpy="0 0 0" xyz="0.000000 0.000000 0.000000"/>
      <inertia ixx="0.000000" ixy="0.000000" ixz="0.000000" iyy="0.000000" iyz="0.000000" izz="0.000000"/>
    </inertial>
  </link>
  <joint name="track_left_joint" type="revolute">
    <origin rpy="0.00000 0.00000 0.00000" xyz="0.00000 0.00000 0.00000"/>
    <axis xyz="0 0 1"/>
    <parent link="talon"/>
    <child link="track_left"/>
    <limit effort="1000.0" lower="-3.141593" upper="3.141593" velocity="0.5"/>
    <dynamics damping="0.0" friction="0.0"/>
  </joint>
  <link name="track_right">
    <inertial>
      <mass value="0.000000"/>
      <origin rpy="0 0 0" xyz="0.000000 0.000000 0.000000"/>
      <inertia ixx="0.000000" ixy="0.000000" ixz="0.000000" iyy="0.000000" iyz="0.000000" izz="0.000000"/>
    </inertial>
  </link>
  <joint name="track_right_joint" type="revolute">
    <origin rpy="0.00000 0.00000 0.00000" xyz="0.00000 0.00000 0.00000"/>
    <axis xyz="0 0 1"/>
    <parent link="talon"/>
    <child link="track_right"/>
    <limit effort="1000.0" lower="-3.141593" upper="3.141593" velocity="0.5"/>
    <dynamics damping="0.0" friction="0.0"/>
  </joint>
  <link name="torso_link0">
    <inertial>
      <mass value="0.000000"/>
      <origin rpy="0 0 0" xyz="0.000000 0.000000 0.000000"/>
      <inertia ixx="0.000000" ixy="0.000000" ixz="0.000000" iyy="0.000000" iyz="0.000000" izz="0.000000"/>
    </inertial>
    <visual>
      <origin rpy="1.57080 1.57080 0" xyz="0.593 0 0"/>
      <geometry>
        <box size="0.1 0.1 0.1"/>
        <!--                    <mesh filename="package://roman_model/meshes/roman_torso_scaled.stl" scale="1 1 1"/> -->
      </geometry>
      <material name="grey">
        <color rgba=".8 .8 .8 1"/>
      </material>
    </visual>
    <collision>
      <origin rpy="3.1415 -1.57080 0" xyz="-.025 0 0"/>
      <geometry>
        <cylinder length="0.145" radius="0.05"/>
      </geometry>
    </collision>
  </link>
  <joint name="torso_joint0" type="fixed">
    <origin rpy="3.14 1.57080 1.57080" xyz="0.27000 0.00000 0.06"/>
    <parent link="talon"/>
    <child link="torso_link0"/>
    <axis xyz="0 0 1"/>
    <limit effort="1000.0" lower="-3.4906" upper="3.4906" velocity="0.5"/>
    <dynamics damping="0" friction="0"/>
  </joint>
  <joint name="torso_joint1" type="revolute">
    <!--            <origin xyz="0.17203 0.00000 0.00000"  rpy="3.14159 -0.00000 0.00000"/> -->
    <origin rpy="3.14159 -0.00000 0.00000" xyz="0.593 0.00000 0.00000"/>
    <axis xyz="1 0 0"/>
    <parent link="torso_link0"/>
    <child link="chest"/>
    <limit effort="1000.0" lower="-6.283185" upper="6.283185" velocity="0.5"/>
    <dynamics damping="1.000000" friction="10.000000"/>
  </joint>
  <link name="chest">
    <inertial>
      <mass value="10.000000"/>
      <origin rpy="0 0 0" xyz="0.000000 0.000000 0.000000"/>
      <inertia ixx="0.000000" ixy="0.000000" ixz="0.000000" iyy="0.000000" iyz="0.000000" izz="0.000000"/>
    </inertial>
    <visual>
      <origin rpy="-1.570796 1.570796 0.000000" xyz="0.013000 0.000000 0.000000"/>
      <geometry>
        <mesh filename="package://roman_model/meshes/sg_chest.stl" scale="1 1 1"/>
      </geometry>
      <material name="grey">
        <color rgba=".8 .8 .8 1"/>
      </material>
    </visual>
    <collision>
      <origin rpy="0 0 0" xyz="0.006500 0.000000 0.000000"/>
      <geometry>
        <box size="0.013000 0.100000 0.250000"/>
      </geometry>
    </collision>
  </link>
  <link name="limb_left_link0">
    <inertial>
      <mass value="0.000000"/>
      <origin rpy="0 0 0" xyz="0.000000 0.000000 0.000000"/>
      <inertia ixx="0.000000" ixy="0.000000" ixz="0.000000" iyy="0.000000" iyz="0.000000" izz="0.000000"/>
    </inertial>
    <visual>
      <origin rpy="0 0 0" xyz="0.000000 0 0"/>
      <geometry>
        <mesh filename="package://roman_model/meshes/robosim_fts.stl" scale="1 1 1"/>
      </geometry>
      <material name="grey">
        <color rgba=".8 .8 .8 1"/>
      </material>
    </visual>
    <collision>
      <origin rpy="3.1415 -1.57080 0" xyz="-.025 0 0"/>
      <geometry>
        <cylinder length="0.145" radius="0.05"/>
      </geometry>
    </collision>
  </link>
  <link name="limb_left_link1">
    <inertial>
      <mass value="0.429000"/>
      <origin rpy="0 0 0" xyz="-0.050402 0.012816 0.000000"/>
      <inertia ixx="0.000741" ixy="-0.000215" ixz="0.000000" iyy="0.002044" iyz="0.000000" izz="0.001885"/>
    </inertial>
    <visual>
      <origin rpy="0 0 0" xyz="0.000000 0 0"/>
      <geometry>
        <mesh filename="package://roman_model/meshes/robosim_pitch_link.stl" scale="1 1 1"/>
      </geometry>
      <material name="grey">
        <color rgba=".8 .8 .8 1"/>
      </material>
    </visual>
    <collision>
      <origin rpy="3.1415 -1.57080 0" xyz="-0.07 0 0"/>
      <geometry>
        <cylinder length="0.07" radius="0.055"/>
      </geometry>
    </collision>
  </link>
  <link name="limb_left_link2">
    <inertial>
      <mass value="3.975000"/>
      <origin rpy="0 0 0" xyz="0.067354 -0.096472 0.000262"/>
      <inertia ixx="0.044712" ixy="-0.030354" ixz="0.000012" iyy="0.033445" iyz="-0.000141" izz="0.074293"/>
    </inertial>
    <visual>
      <origin rpy="0 0 0" xyz="0.000000 0 0"/>
      <geometry>
        <mesh filename="package://roman_model/meshes/robosim_roll_link.stl" scale="1 1 1"/>
      </geometry>
      <material name="grey">
        <color rgba=".8 .8 .8 1"/>
      </material>
    </visual>
    <collision>
      <origin rpy="3.1415 -1.57080 0" xyz="0.065 -0.12 0"/>
      <geometry>
        <cylinder length="0.24" radius="0.055"/>
      </geometry>
    </collision>
    <collision>
      <origin rpy="1.57080 1.57080 0.0" xyz="0.0 -0.035 0"/>
      <geometry>
        <cylinder length="0.075" radius="0.055"/>
      </geometry>
    </collision>
  </link>
  <link name="limb_left_link3">
    <inertial>
      <mass value="0.429000"/>
      <origin rpy="0 0 0" xyz="-0.050402 0.012816 0.000000"/>
      <inertia ixx="0.000741" ixy="-0.000215" ixz="0.000000" iyy="0.002044" iyz="0.000000" izz="0.001885"/>
    </inertial>
    <visual>
      <origin rpy="0 0 0" xyz="0.000000 0 0"/>
      <geometry>
        <mesh filename="package://roman_model/meshes/robosim_pitch_link.stl" scale="1 1 1"/>
      </geometry>
      <material name="grey">
        <color rgba=".8 .8 .8 1"/>
      </material>
    </visual>
    <collision>
      <origin rpy="3.1415 -1.57080 0" xyz="-0.07 0 0"/>
      <geometry>
        <cylinder length="0.07" radius="0.055"/>
      </geometry>
    </collision>
  </link>
  <link name="limb_left_link4">
    <inertial>
      <mass value="3.975000"/>
      <origin rpy="0 0 0" xyz="0.067354 -0.096472 0.000262"/>
      <inertia ixx="0.044712" ixy="-0.030354" ixz="0.000012" iyy="0.033445" iyz="-0.000141" izz="0.074293"/>
    </inertial>
    <visual>
      <origin rpy="0 0 0" xyz="0.000000 0 0"/>
      <geometry>
        <mesh filename="package://roman_model/meshes/robosim_roll_link.stl" scale="1 1 1"/>
      </geometry>
      <material name="grey">
        <color rgba=".8 .8 .8 1"/>
      </material>
    </visual>
    <collision>
      <origin rpy="3.1415 -1.57080 0" xyz="0.065 -0.12 0"/>
      <geometry>
        <cylinder length="0.24" radius="0.055"/>
      </geometry>
    </collision>
    <collision>
      <origin rpy="1.57080 1.57080 0.0" xyz="0.0 -0.035 0"/>
      <geometry>
        <cylinder length="0.075" radius="0.055"/>
      </geometry>
    </collision>
  </link>
  <link name="limb_left_link5">
    <inertial>
      <mass value="0.429000"/>
      <origin rpy="0 0 0" xyz="-0.050402 0.012816 0.000000"/>
      <inertia ixx="0.000741" ixy="-0.000215" ixz="0.000000" iyy="0.002044" iyz="0.000000" izz="0.001885"/>
    </inertial>
    <visual>
      <origin rpy="0 0 0" xyz="0.000000 0 0"/>
      <geometry>
        <mesh filename="package://roman_model/meshes/robosim_pitch_link.stl" scale="1 1 1"/>
      </geometry>
      <material name="grey">
        <color rgba=".8 .8 .8 1"/>
      </material>
    </visual>
    <collision>
      <origin rpy="3.1415 -1.57080 0" xyz="-0.07 0 0"/>
      <geometry>
        <cylinder length="0.07" radius="0.055"/>
      </geometry>
    </collision>
  </link>
  <link name="limb_left_link6">
    <inertial>
      <mass value="3.975000"/>
      <origin rpy="0 0 0" xyz="0.067354 -0.096472 0.000262"/>
      <inertia ixx="0.044712" ixy="-0.030354" ixz="0.000012" iyy="0.033445" iyz="-0.000141" izz="0.074293"/>
    </inertial>
    <visual>
      <origin rpy="0 0 0" xyz="0.000000 0 0"/>
      <geometry>
        <mesh filename="package://roman_model/meshes/robosim_roll_link.stl" scale="1 1 1"/>
      </geometry>
      <material name="grey">
        <color rgba=".8 .8 .8 1"/>
      </material>
    </visual>
    <collision>
      <origin rpy="3.1415 -1.57080 0" xyz="0.065 -0.12 0"/>
      <geometry>
        <cylinder length="0.24" radius="0.055"/>
      </geometry>
    </collision>
    <collision>
      <origin rpy="1.57080 1.57080 0.0" xyz="0.0 -0.035 0"/>
      <geometry>
        <cylinder length="0.075" radius="0.055"/>
      </geometry>
    </collision>
  </link>
  <link name="limb_left_link7">
    <inertial>
      <mass value="1.250000"/>
      <origin rpy="0 0 0" xyz="0.060125 0.002176 -0.006854"/>
      <inertia ixx="0.003190" ixy="0.000303" ixz="-0.000796" iyy="0.007459" iyz="-0.000709" izz="0.007727"/>
    </inertial>
    <visual>
      <origin rpy="0.000000 3.141593 -1.570796" xyz="0.087500 0 0"/>
      <geometry>
        <box size="0.13 0.13 0.11"/>
      </geometry>
      <material name="grey">
        <color rgba=".8 .8 .8 1"/>
      </material>
    </visual>
    <collision>
      <origin rpy="3.1415 -1.57080 0" xyz="0.0875 0 0"/>
      <geometry>
        <box size="0.13 0.13 0.11"/>
      </geometry>
    </collision>
  </link>
  <joint name="limb_left_joint0" type="fixed">
    <origin rpy="0.00000 1.57080 -1.57080" xyz="0.07050 0.02500 -0.10000"/>
    <parent link="chest"/>
    <child link="limb_left_link0"/>
    <axis xyz="0 0 1"/>
    <limit effort="1000.0" lower="-3.4906" upper="3.4906" velocity="0.5"/>
    <dynamics damping="0" friction="0"/>
  </joint>
  <joint name="limb_left_joint1" type="revolute">
    <origin rpy="3.14159 -0.00000 0.00000" xyz="0.17203 0.00000 0.00000"/>
    <axis xyz="1 0 0"/>
    <parent link="limb_left_link0"/>
    <child link="limb_left_link1"/>
    <limit effort="1000.0" lower="-6.283185" upper="6.283185" velocity="0.5"/>
    <dynamics damping="1.000000" friction="10.000000"/>
  </joint>
  <joint name="limb_left_joint2" type="revolute">
    <origin rpy="0.00000 -0.00000 0.00000" xyz="0.00000 0.00000 0.00000"/>
    <axis xyz="0 -1 0"/>
    <parent link="limb_left_link1"/>
    <child link="limb_left_link2"/>
    <limit effort="1000.0" lower="-6.283185" upper="6.283185" velocity="0.5"/>
    <dynamics damping="1.000000" friction="10.000000"/>
  </joint>
  <joint name="limb_left_joint3" type="revolute">
    <origin rpy="0.00000 -0.00000 0.00000" xyz="0.28650 -0.11700 0.00000"/>
    <axis xyz="1 0 0"/>
    <parent link="limb_left_link2"/>
    <child link="limb_left_link3"/>
    <limit effort="1000.0" lower="-6.283185" upper="6.283185" velocity="0.5"/>
    <dynamics damping="1.000000" friction="10.000000"/>
  </joint>
  <joint name="limb_left_joint4" type="revolute">
    <origin rpy="0.00000 -0.00000 0.00000" xyz="0.00000 0.00000 0.00000"/>
    <axis xyz="0 -1 0"/>
    <parent link="limb_left_link3"/>
    <child link="limb_left_link4"/>
    <limit effort="1000.0" lower="-6.283185" upper="6.283185" velocity="0.5"/>
    <dynamics damping="1.000000" friction="10.000000"/>
  </joint>
  <joint name="limb_left_joint5" type="revolute">
    <origin rpy="0.00000 -0.00000 0.00000" xyz="0.28650 -0.11700 0.00000"/>
    <axis xyz="1 0 0"/>
    <parent link="limb_left_link4"/>
    <child link="limb_left_link5"/>
    <limit effort="1000.0" lower="-6.283185" upper="6.283185" velocity="0.5"/>
    <dynamics damping="1.000000" friction="10.000000"/>
  </joint>
  <joint name="limb_left_joint6" type="revolute">
    <origin rpy="0.00000 -0.00000 0.00000" xyz="0.00000 0.00000 0.00000"/>
    <axis xyz="0 -1 0"/>
    <parent link="limb_left_link5"/>
    <child link="limb_left_link6"/>
    <limit effort="1000.0" lower="-6.283185" upper="6.283185" velocity="0.5"/>
    <dynamics damping="1.000000" friction="10.000000"/>
  </joint>
  <joint name="limb_left_joint7" type="revolute">
    <origin rpy="0.00000 -0.00000 0.00000" xyz="0.19250 -0.11700 0.00000"/>
    <axis xyz="1 0 0"/>
    <parent link="limb_left_link6"/>
    <child link="limb_left_link7"/>
    <limit effort="1000.0" lower="-6.283185" upper="6.283185" velocity="0.5"/>
    <dynamics damping="1.000000" friction="10.000000"/>
  </joint>
  <link name="limb_right_link0">
    <inertial>
      <mass value="0.000000"/>
      <origin rpy="0 0 0" xyz="0.000000 0.000000 0.000000"/>
      <inertia ixx="0.000000" ixy="0.000000" ixz="0.000000" iyy="0.000000" iyz="0.000000" izz="0.000000"/>
    </inertial>
    <visual>
      <origin rpy="0 0 0" xyz="0.000000 0 0"/>
      <geometry>
        <mesh filename="package://roman_model/meshes/robosim_fts.stl" scale="1 1 1"/>
      </geometry>
      <material name="grey">
        <color rgba=".8 .8 .8 1"/>
      </material>
    </visual>
    <collision>
      <origin rpy="3.1415 -1.57080 0" xyz="-.025 0 0"/>
      <geometry>
        <cylinder length="0.145" radius="0.05"/>
      </geometry>
    </collision>
  </link>
  <link name="limb_right_link1">
    <inertial>
      <mass value="0.429000"/>
      <origin rpy="0 0 0" xyz="-0.050402 0.012816 0.000000"/>
      <inertia ixx="0.000741" ixy="-0.000215" ixz="0.000000" iyy="0.002044" iyz="0.000000" izz="0.001885"/>
    </inertial>
    <visual>
      <origin rpy="0 0 0" xyz="0.000000 0 0"/>
      <geometry>
        <mesh filename="package://roman_model/meshes/robosim_pitch_link.stl" scale="1 1 1"/>
      </geometry>
      <material name="grey">
        <color rgba=".8 .8 .8 1"/>
      </material>
    </visual>
    <collision>
      <origin rpy="3.1415 -1.57080 0" xyz="-0.07 0 0"/>
      <geometry>
        <cylinder length="0.07" radius="0.055"/>
      </geometry>
    </collision>
  </link>
  <link name="limb_right_link2">
    <inertial>
      <mass value="3.975000"/>
      <origin rpy="0 0 0" xyz="0.067354 -0.096472 0.000262"/>
      <inertia ixx="0.044712" ixy="-0.030354" ixz="0.000012" iyy="0.033445" iyz="-0.000141" izz="0.074293"/>
    </inertial>
    <visual>
      <origin rpy="0 0 0" xyz="0.000000 0 0"/>
      <geometry>
        <mesh filename="package://roman_model/meshes/robosim_roll_link.stl" scale="1 1 1"/>
      </geometry>
      <material name="grey">
        <color rgba=".8 .8 .8 1"/>
      </material>
    </visual>
    <collision>
      <origin rpy="3.1415 -1.57080 0" xyz="0.065 -0.12 0"/>
      <geometry>
        <cylinder length="0.24" radius="0.055"/>
      </geometry>
    </collision>
    <collision>
      <origin rpy="1.57080 1.57080 0.0" xyz="0.0 -0.035 0"/>
      <geometry>
        <cylinder length="0.075" radius="0.055"/>
      </geometry>
    </collision>
  </link>
  <link name="limb_right_link3">
    <inertial>
      <mass value="0.429000"/>
      <origin rpy="0 0 0" xyz="-0.050402 0.012816 0.000000"/>
      <inertia ixx="0.000741" ixy="-0.000215" ixz="0.000000" iyy="0.002044" iyz="0.000000" izz="0.001885"/>
    </inertial>
    <visual>
      <origin rpy="0 0 0" xyz="0.000000 0 0"/>
      <geometry>
        <mesh filename="package://roman_model/meshes/robosim_pitch_link.stl" scale="1 1 1"/>
      </geometry>
      <material name="grey">
        <color rgba=".8 .8 .8 1"/>
      </material>
    </visual>
    <collision>
      <origin rpy="3.1415 -1.57080 0" xyz="-0.07 0 0"/>
      <geometry>
        <cylinder length="0.07" radius="0.055"/>
      </geometry>
    </collision>
  </link>
  <link name="limb_right_link4">
    <inertial>
      <mass value="3.975000"/>
      <origin rpy="0 0 0" xyz="0.067354 -0.096472 0.000262"/>
      <inertia ixx="0.044712" ixy="-0.030354" ixz="0.000012" iyy="0.033445" iyz="-0.000141" izz="0.074293"/>
    </inertial>
    <visual>
      <origin rpy="0 0 0" xyz="0.000000 0 0"/>
      <geometry>
        <mesh filename="package://roman_model/meshes/robosim_roll_link.stl" scale="1 1 1"/>
      </geometry>
      <material name="grey">
        <color rgba=".8 .8 .8 1"/>
      </material>
    </visual>
    <collision>
      <origin rpy="3.1415 -1.57080 0" xyz="0.065 -0.12 0"/>
      <geometry>
        <cylinder length="0.24" radius="0.055"/>
      </geometry>
    </collision>
    <collision>
      <origin rpy="1.57080 1.57080 0.0" xyz="0.0 -0.035 0"/>
      <geometry>
        <cylinder length="0.075" radius="0.055"/>
      </geometry>
    </collision>
  </link>
  <link name="limb_right_link5">
    <inertial>
      <mass value="0.429000"/>
      <origin rpy="0 0 0" xyz="-0.050402 0.012816 0.000000"/>
      <inertia ixx="0.000741" ixy="-0.000215" ixz="0.000000" iyy="0.002044" iyz="0.000000" izz="0.001885"/>
    </inertial>
    <visual>
      <origin rpy="0 0 0" xyz="0.000000 0 0"/>
      <geometry>
        <mesh filename="package://roman_model/meshes/robosim_pitch_link.stl" scale="1 1 1"/>
      </geometry>
      <material name="grey">
        <color rgba=".8 .8 .8 1"/>
      </material>
    </visual>
    <collision>
      <origin rpy="3.1415 -1.57080 0" xyz="-0.07 0 0"/>
      <geometry>
        <cylinder length="0.07" radius="0.055"/>
      </geometry>
    </collision>
  </link>
  <link name="limb_right_link6">
    <inertial>
      <mass value="3.975000"/>
      <origin rpy="0 0 0" xyz="0.067354 -0.096472 0.000262"/>
      <inertia ixx="0.044712" ixy="-0.030354" ixz="0.000012" iyy="0.033445" iyz="-0.000141" izz="0.074293"/>
    </inertial>
    <visual>
      <origin rpy="0 0 0" xyz="0.000000 0 0"/>
      <geometry>
        <mesh filename="package://roman_model/meshes/robosim_roll_link.stl" scale="1 1 1"/>
      </geometry>
      <material name="grey">
        <color rgba=".8 .8 .8 1"/>
      </material>
    </visual>
    <collision>
      <origin rpy="3.1415 -1.57080 0" xyz="0.065 -0.12 0"/>
      <geometry>
        <cylinder length="0.24" radius="0.055"/>
      </geometry>
    </collision>
    <collision>
      <origin rpy="1.57080 1.57080 0.0" xyz="0.0 -0.035 0"/>
      <geometry>
        <cylinder length="0.075" radius="0.055"/>
      </geometry>
    </collision>
  </link>
  <link name="limb_right_link7">
    <inertial>
      <mass value="1.250000"/>
      <origin rpy="0 0 0" xyz="0.060125 0.002176 -0.006854"/>
      <inertia ixx="0.003190" ixy="0.000303" ixz="-0.000796" iyy="0.007459" iyz="-0.000709" izz="0.007727"/>
    </inertial>
    <visual>
      <origin rpy="0.000000 3.141593 -1.570796" xyz="0.087500 0 0"/>
      <geometry>
        <box size="0.13 0.13 0.11"/>
      </geometry>
      <material name="grey">
        <color rgba=".8 .8 .8 1"/>
      </material>
    </visual>
    <collision>
      <origin rpy="3.1415 -1.57080 0" xyz="0.0875 0 0"/>
      <geometry>
        <box size="0.13 0.13 0.11"/>
      </geometry>
    </collision>
  </link>
  <joint name="limb_right_joint0" type="fixed">
    <origin rpy="0.00000 -1.57080 -1.57080" xyz="0.07050 0.02500 0.10000"/>
    <parent link="chest"/>
    <child link="limb_right_link0"/>
    <axis xyz="0 0 1"/>
    <limit effort="1000.0" lower="-3.4906" upper="3.4906" velocity="0.5"/>
    <dynamics damping="0" friction="0"/>
  </joint>
  <joint name="limb_right_joint1" type="revolute">
    <origin rpy="3.14159 -0.00000 0.00000" xyz="0.17203 0.00000 0.00000"/>
    <axis xyz="1 0 0"/>
    <parent link="limb_right_link0"/>
    <child link="limb_right_link1"/>
    <limit effort="1000.0" lower="-6.283185" upper="6.283185" velocity="0.5"/>
    <dynamics damping="1.000000" friction="10.000000"/>
  </joint>
  <joint name="limb_right_joint2" type="revolute">
    <origin rpy="0.00000 -0.00000 0.00000" xyz="0.00000 0.00000 0.00000"/>
    <axis xyz="0 -1 0"/>
    <parent link="limb_right_link1"/>
    <child link="limb_right_link2"/>
    <limit effort="1000.0" lower="-6.283185" upper="6.283185" velocity="0.5"/>
    <dynamics damping="1.000000" friction="10.000000"/>
  </joint>
  <joint name="limb_right_joint3" type="revolute">
    <origin rpy="0.00000 -0.00000 0.00000" xyz="0.28650 -0.11700 0.00000"/>
    <axis xyz="1 0 0"/>
    <parent link="limb_right_link2"/>
    <child link="limb_right_link3"/>
    <limit effort="1000.0" lower="-6.283185" upper="6.283185" velocity="0.5"/>
    <dynamics damping="1.000000" friction="10.000000"/>
  </joint>
  <joint name="limb_right_joint4" type="revolute">
    <origin rpy="0.00000 -0.00000 0.00000" xyz="0.00000 0.00000 0.00000"/>
    <axis xyz="0 -1 0"/>
    <parent link="limb_right_link3"/>
    <child link="limb_right_link4"/>
    <limit effort="1000.0" lower="-6.283185" upper="6.283185" velocity="0.5"/>
    <dynamics damping="1.000000" friction="10.000000"/>
  </joint>
  <joint name="limb_right_joint5" type="revolute">
    <origin rpy="0.00000 -0.00000 0.00000" xyz="0.28650 -0.11700 0.00000"/>
    <axis xyz="1 0 0"/>
    <parent link="limb_right_link4"/>
    <child link="limb_right_link5"/>
    <limit effort="1000.0" lower="-6.283185" upper="6.283185" velocity="0.5"/>
    <dynamics damping="1.000000" friction="10.000000"/>
  </joint>
  <joint name="limb_right_joint6" type="revolute">
    <origin rpy="0.00000 -0.00000 0.00000" xyz="0.00000 0.00000 0.00000"/>
    <axis xyz="0 -1 0"/>
    <parent link="limb_right_link5"/>
    <child link="limb_right_link6"/>
    <limit effort="1000.0" lower="-6.283185" upper="6.283185" velocity="0.5"/>
    <dynamics damping="1.000000" friction="10.000000"/>
  </joint>
  <joint name="limb_right_joint7" type="revolute">
    <origin rpy="0.00000 -0.00000 0.00000" xyz="0.19250 -0.11700 0.00000"/>
    <axis xyz="1 0 0"/>
    <parent link="limb_right_link6"/>
    <child link="limb_right_link7"/>
    <limit effort="1000.0" lower="-6.283185" upper="6.283185" velocity="0.5"/>
    <dynamics damping="1.000000" friction="10.000000"/>
  </joint>
  <xacro:robosimian_r_arm_transmission name="robosimian_r_arm" namespace="false"/>
</robot>

