<?xml version="1.0"?>
<robot xmlns:xacro="http://ros.org/wiki/xacro">
    <xacro:include filename="$(find roman_model)/gazebo/roman_body.gazebo.xacro"/>
    <xacro:include filename="$(find roman_model)/control/roman_body.transmission.xacro"/>
    <xacro:include filename="$(find hector_sensors_description)/urdf/asus_camera.urdf.xacro"/>

    <xacro:macro name="roman_body" params="name parent *origin namespace">
        <joint name="torso_joint0" type="fixed">
            <parent link="${parent}"/>
            <child link="torso_link0"/>
            <insert_block name="origin"/>
        </joint>

        <link name="torso_link0">
            <!-- dummy inertial values -->
            <inertial>
                <mass value="0.003141"/>
                <origin xyz="0 0 0" rpy="0 0 0"/>
                <inertia ixx="0.003141" ixy="0" ixz="0" iyy="0.003141" iyz="0" izz="0.003141"/>
            </inertial>
            <visual>
                <origin xyz="0.593 0 0" rpy="1.57080 1.57080 0"/>
                <geometry>
                   <mesh filename="package://roman_model/meshes/roman_torso.stl" scale="1 1 1"/>
                </geometry>
                <material name="grey">
                    <color rgba="0.8 0.8 0.8 1"/>
                </material>
            </visual>
            <collision>
                <origin xyz="0.2965 0 0" rpy="3.1415 -1.57080 0"/>
                <geometry>
                    <box size="0.20 0.20 0.593"/>
                </geometry>
            </collision>
            <collision>
                <origin xyz="0.2965 0.15 0" rpy="3.1415 -1.57080 0"/>
                <geometry>
                    <box size="0.20 0.10 0.10"/>
                </geometry>
            </collision>
        </link>

        <joint name="torso_joint1" type="revolute">
            <origin xyz="0.593 0 0" rpy="3.14159 0 0"/>
            <axis xyz="1 0 0"/>
            <parent link="torso_link0"/>
            <child link="chest"/>
            <limit effort="1000.0" lower="-6.283185" upper="6.283185" velocity="0.5"/>
            <dynamics damping="1.0" friction="10.0"/>
        </joint>

        <link name="chest">
            <inertial>
                <mass value="10.0"/>
                <origin xyz="0 0 0" rpy="0 0 0"/>
                <!-- dummy moments -->
                <inertia ixx="0.003141" ixy="0" ixz="0" iyy="0.003141" iyz="0" izz="0.003141"/>
            </inertial>
            <visual>
                <origin xyz="0.013 0 0" rpy="-1.570796 1.570796 0"/>
                <geometry>
                    <mesh filename="package://roman_model/meshes/sg_chest.stl" scale="1 1 1"/>
                </geometry>
                <material name="grey">
                    <color rgba="0.8 0.8 0.8 1"/>
                </material>
            </visual>
            <collision>
                <origin xyz="0.0065 0 0" rpy="0 0 0"/>
                <geometry>
<!--                    <box size="0.013 0.1 0.25"/> -->
                    <box size="0.013 0.4 0.4"/>
                </geometry>
            </collision>
            <!-- asus and stuff -->
            <collision>
                <origin xyz="0.05 -0.1645 0.03825" rpy="0 0 0"/>
                <geometry>
                    <box size="0.14 0.10609 0.14"/>
                </geometry>
            </collision>
            <!-- hat -->
            <collision>
                <origin xyz="0.20 0.03 0.0"/>
                <geometry>
                    <box size="0.1 0.16 0.40"/>
                </geometry>
            </collision>
        </link>

        <xacro:asus_camera name="asus" parent="chest">
            <origin xyz="0.05 -0.075 0" rpy="${-M_PI/2} 0.0 -2.09"/>
        </xacro:asus_camera>

        <xacro:roman_body_gazebo name="${name}" namespace="${namespace}"/>
        <xacro:roman_body_transmission name="${name}" namespace="${namespace}"/>
    </xacro:macro>
</robot>
