<?xml version="1.0"?>
<robot xmlns:xacro="http://ros.org/wiki/xacro">
    <xacro:include filename="$(find roman_model)/gazebo/talon.gazebo.xacro"/>
    <xacro:include filename="$(find roman_model)/control/talon.transmission.xacro"/>
    <xacro:include filename="$(find hector_sensors_description)/urdf/hokuyo_utm30lx.urdf.xacro"/>

    <xacro:macro name="talon" params="name namespace">
        <link name="${name}_footprint"/>

        <joint name="${name}_footprint_joint" type="fixed">
            <origin xyz="0 0 0.15203" rpy="0 0 0"/>
            <parent link="${name}_footprint"/>
            <child link="${name}_link"/>
        </joint>

        <link name="${name}_link"/>

        <joint name="${name}_joint" type="fixed">
            <origin xyz="0 0 0" rpy="3.14 0 0"/>
            <parent link="${name}_link"/>
            <child link="talon"/>
        </joint>

        <link name="talon">
            <inertial>
                <mass value="40.0"/>
                <origin xyz="0 0 0" rpy="0 0 0"/>
                <!-- NOTE: dummy values for moment of inertia to keep the -->
                <!-- base from spinning in gazebo -->
                <inertia ixx="1.0" ixy="0" ixz="0" iyy="1.0" iyz="0" izz="1.0"/>
            </inertial>
            <visual>
                <origin xyz="0 0 0" rpy="0 0 0"/>
                <geometry>
<!--                    <box size="0.9 0.6 0.26"/> -->
                    <mesh filename="package://roman_model/meshes/tl1.stl" scale="1 1 1"/>
                </geometry>
                <material name="grey">
                    <color rgba="0.8 0.8 0.8 1"/>
                </material>
            </visual>
            <!-- body -->
            <collision>
                <origin xyz="0 0 0" rpy="0 0 0"/>
                <geometry>
                    <box size="0.9 0.6 0.26"/>
                </geometry>
            </collision>
            <!-- left track -->
            <collision>
                <origin xyz="0 0.26 0" rpy="0 0 0"/>
                <geometry>
                    <box size="0.9 0.08 0.3"/>
                </geometry>
            </collision>
            <!-- right track -->
            <collision>
                <origin xyz="0 -0.26 0" rpy="0 0 0"/>
                <geometry>
                    <box size="0.9 0.08 0.3"/>
                </geometry>
            </collision>
            <!-- back -->
            <collision>
                <origin xyz="-0.325 0 -0.18" rpy="0 0 0"/>
                <geometry>
                    <box size="0.25 0.6 0.1"/>
                </geometry>
            </collision>
        </link>

        <xacro:hokuyo_utm30lx_gpu name="base_laser" parent="base_link" ros_topic="base_scan" update_rate="20.0" ray_count="1080" min_angle="-130" max_angle="130">
            <origin xyz="0.413 0 0.210" rpy="0 0 0"/>
        </xacro:hokuyo_utm30lx_gpu>

        <joint name="track_left_joint" type="revolute">
            <origin xyz="0 0 0" rpy="0 0 0"/>
            <axis xyz="0 0 1"/>
            <parent link="talon"/>
            <child link="track_left"/>
            <limit effort="1000.0" lower="-3.141593" upper="3.141593" velocity="0.5"/>
            <dynamics damping="0.0" friction="0.0"/>
        </joint>

        <link name="track_left">
            <inertial>
                <mass value="0.003141"/>
                <origin xyz="0 0 0" rpy="0 0 0"/>
                <inertia ixx="0.003141" ixy="0" ixz="0" iyy="0.003141" iyz="0" izz="0.003141"/>
            </inertial>
        </link>

        <joint name="track_right_joint" type="revolute">
            <origin xyz="0 0 0" rpy="0 0 0"/>
            <axis xyz="0 0 1"/>
            <parent link="talon"/>
            <child link="track_right"/>
            <limit effort="1000.0" lower="-3.141593" upper="3.141593" velocity="0.5"/>
            <dynamics damping="0.0" friction="0.0"/>
        </joint>

        <link name="track_right">
            <inertial>
                <mass value="0.003141"/>
                <origin xyz="0 0 0" rpy="0 0 0"/>
                <inertia ixx="0.003141" ixy="0" ixz="0" iyy="0.003141" iyz="0" izz="0.003141"/>
            </inertial>
        </link>

        <xacro:talon_gazebo name="${name}" namespace="${namespace}"/>
        <xacro:talon_transmission name="${name}" namespace="${namespace}"/>
    </xacro:macro>
</robot>
