<?xml version="1.0"?>
<robot name="roman_object_manipulator" xmlns:xacro="http://ros.org/wiki/xacro">
    <xacro:include filename="$(find roman_model)/robots/rcta_roman.urdf.xacro"/>

    <link name="z_link"/>
    <joint name="base_link_z_joint" type="prismatic">
        <origin xyz="0 0 0" rpy="0 0 0"/>
        <axis xyz="0 0 1"/>
        <parent link="z_link"/>
        <child link="base_link"/>
        <limit effort="1000.0" velocity="1000.0" lower="-100.0" upper="100.0"/>
    </joint>
</robot>
