<robot name="rs_limb">
  <link name="base_link">
    <visual>
      <origin xyz="0 0 0" rpy="0 0 0" />
      <geometry>
       <box size="0 0 0"/>
      </geometry>
        <material name="white">
	      <color rgba="1 1 1 1" />
        </material>
    </visual>
    <collision group="default">
      <origin rpy="0 0 0" xyz="0 0 0"/>
      <geometry>
         <box size="0 0 0"/>
      </geometry>
    </collision>
  </link>


   <joint name="base_joint" type="fixed">
      <origin xyz="0 0 0"  rpy="1.57 0 0" />
      <parent link="base_link" />
      <child link="limb_1_link0" />
   </joint>
   <link name="limb_1_link0">
      <inertial>
        <mass value="2.500000" />
        <origin xyz="0.000000 0.000000 0.000000" rpy="0 0 0" />
        <inertia ixx="0.000000" ixy="0.000000" ixz="0.000000" iyy="0.000000" iyz="0.000000" izz="0.000000" />
      </inertial>
      <visual>
        <origin xyz="0.000000 0 0" rpy="0 0 0" />
        <geometry>
           <mesh filename="package://surrogate_model/meshes/robosim_fts.stl" scale="1 1 1" />
        </geometry>
        <material name="grey">
	      <color rgba=".8 .8 .8 1" />
        </material>
      </visual>
      <collision group="other">
        <origin rpy="3.1415 -1.57080 0" xyz="-.025 0 0"/>
        <geometry>
          <cylinder length="0.145" radius="0.05"/>
        </geometry>
      </collision>
   </link>

   <link name="limb_1_link1">
      <inertial>
        <mass value="0.429000" />
        <origin xyz="-0.050402 0.012816 0.000000" rpy="0 0 0" />
        <inertia ixx="0.000741" ixy="-0.000215" ixz="0.000000" iyy="0.002044" iyz="0.000000" izz="0.001885" />
      </inertial>
      <visual>
        <origin xyz="0.000000 0 0" rpy="0 0 0" />
        <geometry>
           <mesh filename="package://surrogate_model/meshes/robosim_pitch_link.stl" scale="1 1 1" />
        </geometry>
        <material name="grey">
	      <color rgba=".8 .8 .8 1" />
        </material>
      </visual>
      <collision group="other">
        <origin rpy="3.1415 -1.57080 0" xyz="-0.07 0 0"/>
        <geometry>
          <cylinder length="0.07" radius="0.055"/>
        </geometry>
      </collision>
   </link>

   <link name="limb_1_link2">
      <inertial>
        <mass value="3.975000" />
        <origin xyz="0.067354 -0.096472 0.000262" rpy="0 0 0" />
        <inertia ixx="0.044712" ixy="-0.030354" ixz="0.000012" iyy="0.033445" iyz="-0.000141" izz="0.074293" />
      </inertial>
      <visual>
        <origin xyz="0.000000 0 0" rpy="0 0 0" />
        <geometry>
           <mesh filename="package://surrogate_model/meshes/robosim_roll_link.stl" scale="1 1 1" />
        </geometry>
        <material name="grey">
	      <color rgba=".8 .8 .8 1" />
        </material>
      </visual>
      <collision group="other">
        <origin rpy="3.1415 -1.57080 0" xyz="0.065 -0.12 0"/>
        <geometry>
          <cylinder length="0.24" radius="0.055"/>
        </geometry>
      </collision>
      <collision group="other">
        <origin rpy="1.57080 1.57080 0.0" xyz="0.0 -0.035 0"/>
        <geometry>
          <cylinder length="0.075" radius="0.055"/>
        </geometry>
      </collision>
   </link>

   <link name="limb_1_link3">
      <inertial>
        <mass value="0.429000" />
        <origin xyz="-0.050402 0.012816 0.000000" rpy="0 0 0" />
        <inertia ixx="0.000741" ixy="-0.000215" ixz="0.000000" iyy="0.002044" iyz="0.000000" izz="0.001885" />
      </inertial>
      <visual>
        <origin xyz="0.000000 0 0" rpy="0 0 0" />
        <geometry>
           <mesh filename="package://surrogate_model/meshes/robosim_pitch_link.stl" scale="1 1 1" />
        </geometry>
        <material name="grey">
	      <color rgba=".8 .8 .8 1" />
        </material>
      </visual>
      <collision group="other">
        <origin rpy="3.1415 -1.57080 0" xyz="-0.07 0 0"/>
        <geometry>
          <cylinder length="0.07" radius="0.055"/>
        </geometry>
      </collision>
   </link>

   <link name="limb_1_link4">
      <inertial>
        <mass value="3.975000" />
        <origin xyz="0.067354 -0.096472 0.000262" rpy="0 0 0" />
        <inertia ixx="0.044712" ixy="-0.030354" ixz="0.000012" iyy="0.033445" iyz="-0.000141" izz="0.074293" />
      </inertial>
      <visual>
        <origin xyz="0.000000 0 0" rpy="0 0 0" />
        <geometry>
           <mesh filename="package://surrogate_model/meshes/robosim_roll_link.stl" scale="1 1 1" />
        </geometry>
        <material name="grey">
	      <color rgba=".8 .8 .8 1" />
        </material>
      </visual>
      <collision group="other">
        <origin rpy="3.1415 -1.57080 0" xyz="0.065 -0.12 0"/>
        <geometry>
          <cylinder length="0.24" radius="0.055"/>
        </geometry>
      </collision>
      <collision group="other">
        <origin rpy="1.57080 1.57080 0.0" xyz="0.0 -0.035 0"/>
        <geometry>
          <cylinder length="0.075" radius="0.055"/>
        </geometry>
      </collision>
   </link>

   <link name="limb_1_link5">
      <inertial>
        <mass value="0.429000" />
        <origin xyz="-0.050402 0.012816 0.000000" rpy="0 0 0" />
        <inertia ixx="0.000741" ixy="-0.000215" ixz="0.000000" iyy="0.002044" iyz="0.000000" izz="0.001885" />
      </inertial>
      <visual>
        <origin xyz="0.000000 0 0" rpy="0 0 0" />
        <geometry>
           <mesh filename="package://surrogate_model/meshes/robosim_pitch_link.stl" scale="1 1 1" />
        </geometry>
        <material name="grey">
	      <color rgba=".8 .8 .8 1" />
        </material>
      </visual>
      <collision group="other">
        <origin rpy="3.1415 -1.57080 0" xyz="-0.07 0 0"/>
        <geometry>
          <cylinder length="0.07" radius="0.055"/>
        </geometry>
      </collision>
   </link>

   <link name="limb_1_link6">
      <inertial>
        <mass value="3.975000" />
        <origin xyz="0.067354 -0.096472 0.000262" rpy="0 0 0" />
        <inertia ixx="0.044712" ixy="-0.030354" ixz="0.000012" iyy="0.033445" iyz="-0.000141" izz="0.074293" />
      </inertial>
      <visual>
        <origin xyz="0.000000 0 0" rpy="0 0 0" />
        <geometry>
           <mesh filename="package://surrogate_model/meshes/robosim_roll_link.stl" scale="1 1 1" />
        </geometry>
        <material name="grey">
	      <color rgba=".8 .8 .8 1" />
        </material>
      </visual>
      <collision group="other">
        <origin rpy="3.1415 -1.57080 0" xyz="0.065 -0.12 0"/>
        <geometry>
          <cylinder length="0.24" radius="0.055"/>
        </geometry>
      </collision>
      <collision group="other">
        <origin rpy="1.57080 1.57080 0.0" xyz="0.0 -0.035 0"/>
        <geometry>
          <cylinder length="0.075" radius="0.055"/>
        </geometry>
      </collision>
   </link>

   <link name="limb_1_link7">
      <inertial>
        <mass value="1.250000" />
        <origin xyz="0.060125 0.002176 -0.006854" rpy="0 0 0" />
        <inertia ixx="0.003190" ixy="0.000303" ixz="-0.000796" iyy="0.007459" iyz="-0.000709" izz="0.007727" />
      </inertial>
      <visual>
        <origin xyz="0.087500 0 0" rpy="0.000000 3.141593 -1.570796" />
        <geometry>
           <mesh filename="package://surrogate_model/meshes/robotiq_palm.stl" scale="1 1 1" />
        </geometry>
        <material name="grey">
	      <color rgba=".8 .8 .8 1" />
        </material>
      </visual>
      <collision group="other">
        <origin rpy="3.1415 -1.57080 0" xyz="0.0875 0 0"/>
        <geometry>
          <box size="0.13 0.13 0.11"/>
        </geometry>
      </collision>
      <collision group="other">
        <origin rpy="3.1415 -1.57080 0" xyz="0.0875 0 0"/>
        <geometry>
          <cylinder length="0.0325" radius="0.05"/>
        </geometry>
      </collision>
   </link>

   <joint name="limb_1_joint1" type="revolute">
      <origin xyz="0.17203 0.00000 0.00000"  rpy="3.14159 -0.00000 0.00000" />
      <axis xyz="1 0 0" />
      <parent link="limb_1_link0" />
      <child link="limb_1_link1" />
      <limit effort="1000.0" lower="-6.283185" upper="6.283185" velocity="0.5"/>
      <dynamics damping="1.000000" friction="10.000000"/>
   </joint>

   <joint name="limb_1_joint2" type="revolute">
      <origin xyz="0.00000 0.00000 0.00000"  rpy="0.00000 -0.00000 0.00000" />
      <axis xyz="0 -1 0" />
      <parent link="limb_1_link1" />
      <child link="limb_1_link2" />
      <limit effort="1000.0" lower="-6.283185" upper="6.283185" velocity="0.5"/>
      <dynamics damping="1.000000" friction="10.000000"/>
   </joint>

   <joint name="limb_1_joint3" type="revolute">
      <origin xyz="0.28650 -0.11700 0.00000"  rpy="0.00000 -0.00000 0.00000" />
      <axis xyz="1 0 0" />
      <parent link="limb_1_link2" />
      <child link="limb_1_link3" />
      <limit effort="1000.0" lower="-6.283185" upper="6.283185" velocity="0.5"/>
      <dynamics damping="1.000000" friction="10.000000"/>
   </joint>

   <joint name="limb_1_joint4" type="revolute">
      <origin xyz="0.00000 0.00000 0.00000"  rpy="0.00000 -0.00000 0.00000" />
      <axis xyz="0 -1 0" />
      <parent link="limb_1_link3" />
      <child link="limb_1_link4" />
      <limit effort="1000.0" lower="-6.283185" upper="6.283185" velocity="0.5"/>
      <dynamics damping="1.000000" friction="10.000000"/>
   </joint>

   <joint name="limb_1_joint5" type="revolute">
      <origin xyz="0.28650 -0.11700 0.00000"  rpy="0.00000 -0.00000 0.00000" />
      <axis xyz="1 0 0" />
      <parent link="limb_1_link4" />
      <child link="limb_1_link5" />
      <limit effort="1000.0" lower="-6.283185" upper="6.283185" velocity="0.5"/>
      <dynamics damping="1.000000" friction="10.000000"/>
   </joint>

   <joint name="limb_1_joint6" type="revolute">
      <origin xyz="0.00000 0.00000 0.00000"  rpy="0.00000 -0.00000 0.00000" />
      <axis xyz="0 -1 0" />
      <parent link="limb_1_link5" />
      <child link="limb_1_link6" />
      <limit effort="1000.0" lower="-6.283185" upper="6.283185" velocity="0.5"/>
      <dynamics damping="1.000000" friction="10.000000"/>
   </joint>

   <joint name="limb_1_joint7" type="revolute">
      <origin xyz="0.19250 -0.11700 0.00000"  rpy="0.00000 -0.00000 0.00000" />
      <axis xyz="1 0 0" />
      <parent link="limb_1_link6" />
      <child link="limb_1_link7" />
      <limit effort="1000.0" lower="-6.283185" upper="6.283185" velocity="0.5"/>
      <dynamics damping="1.000000" friction="10.000000"/>
   </joint>

   <link name="limb_1_finger0_link_actuator">
      <inertial>
        <mass value="0" />
        <origin xyz="0 0 0" rpy="0 0 0" />
        <inertia ixx="0" ixy="0" ixz="0" iyy="0" iyz="0" izz="0" />
      </inertial>
   </link>

   <link name="limb_1_scissor_link_actuator">
      <inertial>
        <mass value="0" />
        <origin xyz="0 0 0" rpy="0 0 0" />
        <inertia ixx="0" ixy="0" ixz="0" iyy="0" iyz="0" izz="0" />
      </inertial>
   </link>

   <link name="limb_1_finger0_link0">
      <inertial>
        <mass value="0.000000" />
        <origin xyz="0.000000 0.000000 0.000000" rpy="0 0 0" />
        <inertia ixx="0.000000" ixy="0.000000" ixz="0.000000" iyy="0.000000" iyz="0.000000" izz="0.000000" />
      </inertial>
      <visual>
        <origin xyz="0.020000 0.000000 0.000000" rpy="0 0 0.000000" />
        <geometry>
           <mesh filename="package://surrogate_model/meshes/robotiq_link0.stl" scale="1 1 1" />
        </geometry>
        <material name="grey">
	      <color rgba=".8 .8 .8 1" />
        </material>
      </visual>
      <collision group="default">
        <origin rpy="0 0 0" xyz="0.004714 0.007938 0"/>
        <geometry>
           <box size="0.043105 0.044450 0.030734"/>
        </geometry>
      </collision>
   </link>

   <link name="limb_1_finger0_link1">
      <inertial>
        <mass value="0.000000" />
        <origin xyz="0.000000 0.000000 0.000000" rpy="0 0 0" />
        <inertia ixx="0.000000" ixy="0.000000" ixz="0.000000" iyy="0.000000" iyz="0.000000" izz="0.000000" />
      </inertial>
      <visual>
        <origin xyz="0.050000 -0.028000 0.000000" rpy="0 0 -0.520000" />
        <geometry>
           <mesh filename="package://surrogate_model/meshes/robotiq_link1.stl" scale="1 1 1" />
        </geometry>
        <material name="grey">
	      <color rgba=".8 .8 .8 1" />
        </material>
      </visual>
      <collision group="default">
        <origin rpy="0 0 -0.52" xyz="0.020477 -0.023993 0.000000"/>
        <geometry>
           <box size="0.105099 0.045175 0.030734"/>
        </geometry>
      </collision>
   </link>

   <link name="limb_1_finger0_link2">
      <inertial>
        <mass value="0.000000" />
        <origin xyz="0.000000 0.000000 0.000000" rpy="0 0 0" />
        <inertia ixx="0.000000" ixy="0.000000" ixz="0.000000" iyy="0.000000" iyz="0.000000" izz="0.000000" />
      </inertial>
      <visual>
        <origin xyz="0.039000 0.000000 0.007500" rpy="0 0 0.000000" />
        <geometry>
           <mesh filename="package://surrogate_model/meshes/robotiq_link2.stl" scale="1 1 1" />
        </geometry>
        <material name="grey">
	      <color rgba=".8 .8 .8 1" />
        </material>
      </visual>
      <collision group="default">
        <origin rpy="0 0 0" xyz="0.011875 -0.010212 -0.000547"/>
        <geometry>
           <box size="0.071823 0.035409 0.030734"/>
        </geometry>
      </collision>
   </link>

   <link name="limb_1_finger0_link3">
      <inertial>
        <mass value="0.055000" />
        <origin xyz="0.000000 0.000000 0.000000" rpy="0 0 0" />
        <inertia ixx="0.000000" ixy="0.000000" ixz="0.000000" iyy="0.000000" iyz="0.000000" izz="0.000000" />
      </inertial>
      <visual>
        <origin xyz="0.000000 0.000000 0.000000" rpy="0 0 0.520000" />
        <geometry>
           <mesh filename="package://surrogate_model/meshes/robotiq_link3.stl" scale="1 1 1" />
        </geometry>
        <material name="grey">
	      <color rgba=".8 .8 .8 1" />
        </material>
      </visual>
      <collision group="default">
        <origin rpy="0 0 0.52" xyz="0.011269 0.000810 0.000000"/>
        <geometry>
           <box size="0.055837 0.025669 0.030734"/>
        </geometry>
      </collision>
   </link>

   <link name="limb_1_finger1_link_actuator">
      <inertial>
        <mass value="0" />
        <origin xyz="0 0 0" rpy="0 0 0" />
        <inertia ixx="0" ixy="0" ixz="0" iyy="0" iyz="0" izz="0" />
      </inertial>
   </link>

   <link name="limb_1_finger1_link0">
      <inertial>
        <mass value="0.000000" />
        <origin xyz="0.000000 0.000000 0.000000" rpy="0 0 0" />
        <inertia ixx="0.000000" ixy="0.000000" ixz="0.000000" iyy="0.000000" iyz="0.000000" izz="0.000000" />
      </inertial>
      <visual>
        <origin xyz="0.020000 0.000000 0.000000" rpy="0 0 0.000000" />
        <geometry>
           <mesh filename="package://surrogate_model/meshes/robotiq_link0.stl" scale="1 1 1" />
        </geometry>
        <material name="grey">
	      <color rgba=".8 .8 .8 1" />
        </material>
      </visual>
      <collision group="default">
        <origin rpy="0 0 0" xyz="0.004714 0.007938 0"/>
        <geometry>
           <box size="0.043105 0.044450 0.030734"/>
        </geometry>
      </collision>
   </link>

   <link name="limb_1_finger1_link1">
      <inertial>
        <mass value="0.000000" />
        <origin xyz="0.000000 0.000000 0.000000" rpy="0 0 0" />
        <inertia ixx="0.000000" ixy="0.000000" ixz="0.000000" iyy="0.000000" iyz="0.000000" izz="0.000000" />
      </inertial>
      <visual>
        <origin xyz="0.050000 -0.028000 0.000000" rpy="0 0 -0.520000" />
        <geometry>
           <mesh filename="package://surrogate_model/meshes/robotiq_link1.stl" scale="1 1 1" />
        </geometry>
        <material name="grey">
	      <color rgba=".8 .8 .8 1" />
        </material>
      </visual>
      <collision group="default">
        <origin rpy="0 0 -0.52" xyz="0.020477 -0.023993 0.000000"/>
        <geometry>
           <box size="0.105099 0.045175 0.030734"/>
        </geometry>
      </collision>
   </link>

   <link name="limb_1_finger1_link2">
      <inertial>
        <mass value="0.000000" />
        <origin xyz="0.000000 0.000000 0.000000" rpy="0 0 0" />
        <inertia ixx="0.000000" ixy="0.000000" ixz="0.000000" iyy="0.000000" iyz="0.000000" izz="0.000000" />
      </inertial>
      <visual>
        <origin xyz="0.039000 0.000000 0.007500" rpy="0 0 0.000000" />
        <geometry>
           <mesh filename="package://surrogate_model/meshes/robotiq_link2.stl" scale="1 1 1" />
        </geometry>
        <material name="grey">
	      <color rgba=".8 .8 .8 1" />
        </material>
      </visual>
      <collision group="default">
        <origin rpy="0 0 0" xyz="0.011875 -0.010212 -0.000547"/>
        <geometry>
           <box size="0.071823 0.035409 0.030734"/>
        </geometry>
      </collision>
   </link>

   <link name="limb_1_finger1_link3">
      <inertial>
        <mass value="0.055000" />
        <origin xyz="0.000000 0.000000 0.000000" rpy="0 0 0" />
        <inertia ixx="0.000000" ixy="0.000000" ixz="0.000000" iyy="0.000000" iyz="0.000000" izz="0.000000" />
      </inertial>
      <visual>
        <origin xyz="0.000000 0.000000 0.000000" rpy="0 0 0.520000" />
        <geometry>
           <mesh filename="package://surrogate_model/meshes/robotiq_link3.stl" scale="1 1 1" />
        </geometry>
        <material name="grey">
	      <color rgba=".8 .8 .8 1" />
        </material>
      </visual>
      <collision group="default">
        <origin rpy="0 0 0.52" xyz="0.011269 0.000810 0.000000"/>
        <geometry>
           <box size="0.055837 0.025669 0.030734"/>
        </geometry>
      </collision>
   </link>

   <link name="limb_1_finger2_link_actuator">
      <inertial>
        <mass value="0" />
        <origin xyz="0 0 0" rpy="0 0 0" />
        <inertia ixx="0" ixy="0" ixz="0" iyy="0" iyz="0" izz="0" />
      </inertial>
   </link>

   <link name="limb_1_finger2_link0">
      <inertial>
        <mass value="0.000000" />
        <origin xyz="0.000000 0.000000 0.000000" rpy="0 0 0" />
        <inertia ixx="0.000000" ixy="0.000000" ixz="0.000000" iyy="0.000000" iyz="0.000000" izz="0.000000" />
      </inertial>
      <visual>
        <origin xyz="0.020000 0.000000 0.000000" rpy="0 0 0.000000" />
        <geometry>
           <mesh filename="package://surrogate_model/meshes/robotiq_link0.stl" scale="1 1 1" />
        </geometry>
        <material name="grey">
	      <color rgba=".8 .8 .8 1" />
        </material>
      </visual>
      <collision group="default">
        <origin rpy="0 0 0" xyz="0.004714 0.007938 0"/>
        <geometry>
           <box size="0.043105 0.044450 0.030734"/>
        </geometry>
      </collision>
   </link>

   <link name="limb_1_finger2_link1">
      <inertial>
        <mass value="0.000000" />
        <origin xyz="0.000000 0.000000 0.000000" rpy="0 0 0" />
        <inertia ixx="0.000000" ixy="0.000000" ixz="0.000000" iyy="0.000000" iyz="0.000000" izz="0.000000" />
      </inertial>
      <visual>
        <origin xyz="0.050000 -0.028000 0.000000" rpy="0 0 -0.520000" />
        <geometry>
           <mesh filename="package://surrogate_model/meshes/robotiq_link1.stl" scale="1 1 1" />
        </geometry>
        <material name="grey">
	      <color rgba=".8 .8 .8 1" />
        </material>
      </visual>
      <collision group="default">
        <origin rpy="0 0 -0.52" xyz="0.020477 -0.023993 0.000000"/>
        <geometry>
           <box size="0.105099 0.045175 0.030734"/>
        </geometry>
      </collision>
   </link>

   <link name="limb_1_finger2_link2">
      <inertial>
        <mass value="0.000000" />
        <origin xyz="0.000000 0.000000 0.000000" rpy="0 0 0" />
        <inertia ixx="0.000000" ixy="0.000000" ixz="0.000000" iyy="0.000000" iyz="0.000000" izz="0.000000" />
      </inertial>
      <visual>
        <origin xyz="0.039000 0.000000 0.007500" rpy="0 0 0.000000" />
        <geometry>
           <mesh filename="package://surrogate_model/meshes/robotiq_link2.stl" scale="1 1 1" />
        </geometry>
        <material name="grey">
	      <color rgba=".8 .8 .8 1" />
        </material>
      </visual>
      <collision group="default">
        <origin rpy="0 0 0" xyz="0.011875 -0.010212 -0.000547"/>
        <geometry>
           <box size="0.071823 0.035409 0.030734"/>
        </geometry>
      </collision>
   </link>

   <link name="limb_1_finger2_link3">
      <inertial>
        <mass value="0.055000" />
        <origin xyz="0.000000 0.000000 0.000000" rpy="0 0 0" />
        <inertia ixx="0.000000" ixy="0.000000" ixz="0.000000" iyy="0.000000" iyz="0.000000" izz="0.000000" />
      </inertial>
      <visual>
        <origin xyz="0.000000 0.000000 0.000000" rpy="0 0 0.520000" />
        <geometry>
           <mesh filename="package://surrogate_model/meshes/robotiq_link3.stl" scale="1 1 1" />
        </geometry>
        <material name="grey">
	      <color rgba=".8 .8 .8 1" />
        </material>
      </visual>
      <collision group="default">
        <origin rpy="0 0 0.52" xyz="0.011269 0.000810 0.000000"/>
        <geometry>
           <box size="0.055837 0.025669 0.030734"/>
        </geometry>
      </collision>
   </link>

   <joint name="limb_1_scissor_actuator" type="continuous">
      <parent link="limb_1_link7" />
      <child link="limb_1_scissor_link_actuator" />
   </joint>

   <joint name="limb_1_finger0_actuator" type="continuous">
      <parent link="limb_1_link7" />
      <child link="limb_1_finger0_link_actuator" />
   </joint>

   <joint name="limb_1_palm_finger0_joint" type="continuous">
      <parent link="limb_1_link7" />
      <child link="limb_1_finger0_link0" />
      <axis xyz="0 1 0" />
      <origin xyz="0.10890 -0.04550 -0.03600"  rpy="0.00000 -0.00000 0.00000" />
      <limit effort="100.0" lower="-0.16" upper="0.25" velocity="0.5"/>
   </joint>

   <joint name="limb_1_finger1_actuator" type="continuous">
      <parent link="limb_1_link7" />
      <child link="limb_1_finger1_link_actuator" />
   </joint>

   <joint name="limb_1_palm_finger1_joint" type="continuous">
      <parent link="limb_1_link7" />
      <child link="limb_1_finger1_link0" />
      <axis xyz="0 1 0" />
      <origin xyz="0.10890 -0.04550 0.03600"  rpy="0.00000 -0.00000 0.00000" />
      <limit effort="100.0" lower="-0.16" upper="0.25" velocity="0.5"/>
   </joint>

   <joint name="limb_1_finger2_actuator" type="continuous">
      <parent link="limb_1_link7" />
      <child link="limb_1_finger2_link_actuator" />
   </joint>

   <joint name="limb_1_palm_finger2_joint" type="continuous">
      <parent link="limb_1_link7" />
      <child link="limb_1_finger2_link0" />
      <axis xyz="0 0 1" />
      <origin xyz="0.10890 0.04550 0.00000"  rpy="3.14159 -0.00000 0.00000" />
      <limit effort="100.0" lower="-0.16" upper="0.25" velocity="0.5"/>
   </joint>

   <joint name="limb_1_finger0_joint0" type="revolute">
      <parent link="limb_1_finger0_link0"/>
      <child link="limb_1_finger0_link1" />
      <axis xyz="0 0 1" />
      <origin xyz="0.02000 0.00000 0.00000"  rpy="0.00000 -0.00000 0.00000" />
      <limit effort="100.0" lower="0.000000" upper="3.141593" velocity="0.5"/>
   </joint>

   <joint name="limb_1_finger1_joint0" type="revolute">
      <parent link="limb_1_finger1_link0"/>
      <child link="limb_1_finger1_link1" />
      <axis xyz="0 0 1" />
      <origin xyz="0.02000 0.00000 0.00000"  rpy="0.00000 -0.00000 0.00000" />
      <limit effort="100.0" lower="0.000000" upper="3.141593" velocity="0.5"/>
   </joint>

   <joint name="limb_1_finger2_joint0" type="revolute">
      <parent link="limb_1_finger2_link0"/>
      <child link="limb_1_finger2_link1" />
      <axis xyz="0 0 1" />
      <origin xyz="0.02000 0.00000 0.00000"  rpy="0.00000 -0.00000 0.00000" />
      <limit effort="100.0" lower="0.000000" upper="3.141593" velocity="0.5"/>
   </joint>

   <joint name="limb_1_finger0_joint1" type="revolute">
      <parent link="limb_1_finger0_link1"/>
      <child link="limb_1_finger0_link2" />
      <axis xyz="0 0 1" />
      <origin xyz="0.05000 -0.02800 0.00000"  rpy="0.00000 0.00000 -0.52000" />
      <limit effort="100.0" lower="0.000000" upper="3.141593" velocity="0.5"/>
   </joint>

   <joint name="limb_1_finger1_joint1" type="revolute">
      <parent link="limb_1_finger1_link1"/>
      <child link="limb_1_finger1_link2" />
      <axis xyz="0 0 1" />
      <origin xyz="0.05000 -0.02800 0.00000"  rpy="0.00000 0.00000 -0.52000" />
      <limit effort="100.0" lower="0.000000" upper="3.141593" velocity="0.5"/>
   </joint>

   <joint name="limb_1_finger2_joint1" type="revolute">
      <parent link="limb_1_finger2_link1"/>
      <child link="limb_1_finger2_link2" />
      <axis xyz="0 0 1" />
      <origin xyz="0.05000 -0.02800 0.00000"  rpy="0.00000 0.00000 -0.52000" />
      <limit effort="100.0" lower="0.000000" upper="3.141593" velocity="0.5"/>
   </joint>

   <joint name="limb_1_finger0_joint2" type="revolute">
      <parent link="limb_1_finger0_link2"/>
      <child link="limb_1_finger0_link3" />
      <axis xyz="0 0 1" />
      <origin xyz="0.03900 0.00000 0.00000"  rpy="0.00000 -0.00000 0.00000" />
      <limit effort="100.0" lower="0.000000" upper="3.141593" velocity="0.5"/>
   </joint>

   <joint name="limb_1_finger1_joint2" type="revolute">
      <parent link="limb_1_finger1_link2"/>
      <child link="limb_1_finger1_link3" />
      <axis xyz="0 0 1" />
      <origin xyz="0.03900 0.00000 0.00000"  rpy="0.00000 -0.00000 0.00000" />
      <limit effort="100.0" lower="0.000000" upper="3.141593" velocity="0.5"/>
   </joint>

   <joint name="limb_1_finger2_joint2" type="revolute">
      <parent link="limb_1_finger2_link2"/>
      <child link="limb_1_finger2_link3" />
      <axis xyz="0 0 1" />
      <origin xyz="0.03900 0.00000 0.00000"  rpy="0.00000 -0.00000 0.00000" />
      <limit effort="100.0" lower="0.000000" upper="3.141593" velocity="0.5"/>
   </joint>

</robot>
